#VRML_SIM R2023b utf8

EXTERNPROTO "https://raw.githubusercontent.com/cyberbotics/webots/R2022b/projects/objects/backgrounds/protos/TexturedBackground.proto"
EXTERNPROTO "https://raw.githubusercontent.com/cyberbotics/webots/R2022b/projects/objects/backgrounds/protos/TexturedBackgroundLight.proto"

WorldInfo {
  info [
    "A simple RCJ Soccer game simulated using Webots."
  ]
  title "RCJ Soccer Sim"
  optimalThreadCount 8
}
Viewpoint {
  orientation -0.5773502691896258 0.5773502691896258 0.5773502691896258 2.0944
  position 5.8656118744017e-06 5.865628460987897e-06 4.995903284767996
}
TexturedBackground {
}
TexturedBackgroundLight {
}
DEF SOCCER_FIELD Solid {
  children [
    DEF GROUND Pose {
      rotation 0 0 1 1.5707996938995747
      children [
        Shape {
          appearance PBRAppearance {
            baseColorMap ImageTexture {
              url [
                "soccer/soccer-256.jpg"
              ]
            }
            roughness 1
            metalness 0
          }
          geometry Plane {
            size 1.5 1.5
          }
        }
      ]
    }
    DEF YELLOW_GOAL_GROUND Shape {
      appearance PBRAppearance {
        baseColorMap ImageTexture {
          url [
            "soccer/soccer-256.jpg"
          ]
        }
        roughness 1
        metalness 0
      }
      geometry IndexedFaceSet {
        coord Coordinate {
          point [
            -0.75 -0.95 0
            -0.75 -0.75 0
            0.75 -0.75 0
            0.75 -0.95 0
          ]
        }
        texCoord TextureCoordinate {
          point [
            0 0
            0 0
            0 0
            0 0
          ]
        }
        ccw FALSE
        coordIndex [
          0, 1, 2, 3
        ]
        texCoordIndex [
          0, 1, 2, 3
        ]
      }
    }
    DEF BLUE_GOAL_GROUND Shape {
      appearance PBRAppearance {
        baseColorMap ImageTexture {
          url [
            "soccer/soccer-256.jpg"
          ]
        }
        roughness 1
        metalness 0
      }
      geometry IndexedFaceSet {
        coord Coordinate {
          point [
            -0.75 0.95 0
            -0.75 0.75 0
            0.75 0.75 0
            0.75 0.95 0
          ]
        }
        texCoord TextureCoordinate {
          point [
            0 0
            0 0
            0 0
            0 0
          ]
        }
        coordIndex [
          0, 1, 2, 3
        ]
        texCoordIndex [
          0, 1, 2, 3
        ]
      }
    }
    DEF NORTH_WALL Shape {
      appearance DEF WALL_APPEARANCE PBRAppearance {
        baseColor 0.388235 0.388235 0.388235
        roughness 1
        metalness 0
      }
      geometry IndexedFaceSet {
        coord Coordinate {
          point [
            -0.66 -0.76 0
            -0.21 -0.76 0
            -0.21 -0.75 0
            -0.59 -0.75 0
            -0.65 -0.69 0
            -0.65 0.69 0
            -0.59 0.75 0
            -0.21 0.75 0
            -0.21 0.76 0
            -0.65 0.76 0
            -0.66 0.76 0
            -0.66 -0.76 0.09
            -0.21 -0.76 0.09
            -0.21 -0.75 0.09
            -0.59 -0.75 0.09
            -0.65 -0.69 0.09
            -0.65 0.69 0.09
            -0.59 0.75 0.09
            -0.21 0.75 0.09
            -0.21 0.76 0.09
            -0.65 0.76 0.09
            -0.66 0.76 0.09
          ]
        }
        coordIndex [
          0, 10, 9, -1, 9, 8, 7, -1, 9, 7, 6, -1, 2, 1, 0, -1, 3, 2, 0, -1, 9, 6, 5, -1, 4, 3, 0, -1, 0, 9, 5, -1, 0, 5, 4, -1, 11, 12, 13, -1, 11, 13, 14, -1, 20, 21, 11, -1, 18, 19, 20, -1, 17, 18, 20, -1, 11, 14, 15, -1, 16, 17, 20, -1, 11, 15, 16, -1, 11, 16, 20, -1, 0, 1, 12, 11, -1, 1, 2, 13, 12, -1, 2, 3, 14, 13, -1, 3, 4, 15, 14, -1, 4, 5, 16, 15, -1, 5, 6, 17, 16, -1, 6, 7, 18, 17, -1, 7, 8, 19, 18, -1, 8, 9, 20, 19, -1, 9, 10, 21, 20, -1, 10, 0, 11, 21, -1
        ]
      }
    }
    DEF SOUTH_WALL Shape {
      appearance USE WALL_APPEARANCE
      geometry IndexedFaceSet {
        coord Coordinate {
          point [
            0.66 -0.76 0
            0.66 0.76 0
            0.65 0.76 0
            0.21 0.76 0
            0.21 0.75 0
            0.59 0.75 0
            0.65 0.69 0
            0.65 -0.69 0
            0.59 -0.75 0
            0.21 -0.75 0
            0.21 -0.76 0
            0.66 -0.76 0.09
            0.66 0.76 0.09
            0.65 0.76 0.09
            0.21 0.76 0.09
            0.21 0.75 0.09
            0.59 0.75 0.09
            0.65 0.69 0.09
            0.65 -0.69 0.09
            0.59 -0.75 0.09
            0.21 -0.75 0.09
            0.21 -0.76 0.09
          ]
        }
        coordIndex [
          0, 10, 9, -1, 0, 9, 8, -1, 2, 1, 0, -1, 4, 3, 2, -1, 5, 4, 2, -1, 0, 8, 7, -1, 6, 5, 2, -1, 0, 7, 6, -1, 0, 6, 2, -1, 11, 12, 13, -1, 13, 14, 15, -1, 13, 15, 16, -1, 20, 21, 11, -1, 19, 20, 11, -1, 13, 16, 17, -1, 18, 19, 11, -1, 11, 13, 17, -1, 11, 17, 18, -1, 0, 1, 12, 11, -1, 1, 2, 13, 12, -1, 2, 3, 14, 13, -1, 3, 4, 15, 14, -1, 4, 5, 16, 15, -1, 5, 6, 17, 16, -1, 6, 7, 18, 17, -1, 7, 8, 19, 18, -1, 8, 9, 20, 19, -1, 9, 10, 21, 20, -1, 10, 0, 11, 21, -1
        ]
      }
    }
    DEF YELLOW_GOAL Shape {
      appearance PBRAppearance {
        baseColor 1 1 0
        roughness 1
        metalness 0
      }
      geometry IndexedFaceSet {
        coord Coordinate {
          point [
            -0.21 -0.86 0
            0.21 -0.86 0
            0.21 -0.75 0
            0.2 -0.75 0
            0.2 -0.85 0
            -0.2 -0.85 0
            -0.2 -0.75 0
            -0.21 -0.75 0
            -0.21 -0.86 0
            -0.21 -0.86 0.12
            0.21 -0.86 0.12
            0.21 -0.75 0.12
            0.2 -0.75 0.12
            0.2 -0.85 0.12
            -0.2 -0.85 0.12
            -0.2 -0.75 0.12
            -0.21 -0.75 0.12
            -0.21 -0.86 0.12
          ]
        }
        coordIndex [
          0, 1, 2, 3, 4, 5, 6, 7, 8, -1, 0, 1, 10, 9, -1, 1, 2, 11, 10, -1, 2, 3, 12, 11, -1, 3, 4, 13, 12, -1, 4, 5, 14, 13, -1, 5, 6, 15, 14, -1, 6, 7, 16, 15, -1, 7, 8, 17, 16, -1
        ]
      }
    }
    DEF BLUE_GOAL Shape {
      appearance PBRAppearance {
        baseColor 0 0 1
        roughness 1
        metalness 0
      }
      geometry IndexedFaceSet {
        coord Coordinate {
          point [
            -0.21 0.86 0
            -0.21 0.75 0
            -0.2 0.75 0
            -0.2 0.85 0
            0.2 0.85 0
            0.2 0.75 0
            0.21 0.75 0
            0.21 0.86 0
            -0.21 0.86 0
            -0.21 0.86 0.12
            -0.21 0.75 0.12
            -0.2 0.75 0.12
            -0.2 0.85 0.12
            0.2 0.85 0.12
            0.2 0.75 0.12
            0.21 0.75 0.12
            0.21 0.86 0.12
            -0.21 0.86 0.12
          ]
        }
        coordIndex [
          0, 1, 2, 3, 4, 5, 6, 7, 8, -1, 0, 1, 10, 9, -1, 1, 2, 11, 10, -1, 2, 3, 12, 11, -1, 3, 4, 13, 12, -1, 4, 5, 14, 13, -1, 5, 6, 15, 14, -1, 6, 7, 16, 15, -1, 7, 8, 17, 16, -1
        ]
      }
    }
  ]
  name "soccer field"
  boundingObject Group {
    children [
      USE GROUND
      DEF NOTH_BBOX Pose {
        translation 0.655 0 0.045
        children [
          Box {
            size 0.01 1.5 0.09
          }
        ]
      }
      DEF SOUTH_BBOX Pose {
        translation -0.655 0 0.045
        children [
          Box {
            size 0.01 1.5 0.09
          }
        ]
      }
      DEF NW_BBOX Pose {
        translation 0.43 0.755 0.045
        children [
          Box {
            size 0.435 0.01 0.09
          }
        ]
      }
      DEF NE_BBOX Pose {
        translation 0.43 -0.755 0.045
        children [
          Box {
            size 0.435 0.01 0.09
          }
        ]
      }
      DEF SW_BBOX Pose {
        translation -0.43 0.755 0.045
        children [
          Box {
            size 0.435 0.01 0.09
          }
        ]
      }
      DEF SE_BBOX Pose {
        translation -0.43 -0.755 0.045
        children [
          Box {
            size 0.435 0.01 0.09
          }
        ]
      }
      DEF NWC_BBOX Pose {
        translation -0.62 -0.725 0.045
        rotation 0 0 1 -0.7853
        children [
          Box {
            size 0.09 0.01 0.09
          }
        ]
      }
      DEF NEC_BBOX Pose {
        translation -0.62 0.725 0.045
        rotation 0 0 1 0.7853
        children [
          Box {
            size 0.09 0.01 0.09
          }
        ]
      }
      DEF SWC_BBOX Pose {
        translation 0.62 -0.725 0.045
        rotation 0 0 1 0.7853
        children [
          Box {
            size 0.09 0.01 0.09
          }
        ]
      }
      DEF SEC_BBOX Pose {
        translation 0.62 0.725 0.045
        rotation 0 0 1 -0.7853
        children [
          Box {
            size 0.09 0.01 0.09
          }
        ]
      }
      DEF YG_BBOX Pose {
        translation 0 0.855 0.061
        children [
          Box {
            size 0.42 0.01 0.12
          }
        ]
      }
      DEF BG_BBOX Pose {
        translation 0 -0.855 0.061
        children [
          Box {
            size 0.42 0.01 0.12
          }
        ]
      }
      DEF BGS_BBOX Pose {
        translation -0.205 -0.8 0.061
        children [
          Box {
            size 0.01 0.1 0.12
          }
        ]
      }
      DEF BGN_BBOX Pose {
        translation 0.205 -0.8 0.061
        children [
          Box {
            size 0.01 0.1 0.12
          }
        ]
      }
      DEF YGS_BBOX Pose {
        translation -0.205 0.8 0.061
        children [
          Box {
            size 0.01 0.1 0.12
          }
        ]
      }
      DEF YGN_BBOX Pose {
        translation 0.205 0.8 0.061
        children [
          Box {
            size 0.01 0.1 0.12
          }
        ]
      }
    ]
  }
  locked TRUE
}
DEF BALL Robot {
  translation -0.14056456709971382 0.1775234887033005 0.02092146406188199
  rotation 0.7258609412627006 -0.654976972819668 0.21007393704410343 2.9745356386659068
  children [
    DEF FOOTBALL_SHAPE Shape {
      appearance PBRAppearance {
        baseColorMap ImageTexture {
          url [
            "soccer/football_base_color.jpg"
          ]
        }
        roughness 0.4
        metalness 0
        normalMap ImageTexture {
          url [
            "soccer/football_normal.jpg"
          ]
        }
      }
      geometry Sphere {
        radius 0.021
        subdivision 3
      }
    }
    Emitter {
      name "ball emitter"
      type "infra-red"
      range 0.6
      channel 4
      baudRate 115200
      allowedChannels [
        4
      ]
    }
  ]
  name "soccer ball"
  model "soccer ball"
  boundingObject USE FOOTBALL_SHAPE
  physics Physics {
    density -1
    mass 0.05
  }
  recognitionColors [
    1 1 1
    0 0 0
  ]
  controller "rcj_soccer_ball"
  synchronization FALSE
  linearVelocity -0.049193586901851834 -0.18201883346352557 4.3723014254771754e-07
  angularVelocity 8.667563498263123 -2.3425517572310395 10.8851351673814
}
DEF B1 Robot {
  translation 0.2682954083277498 0.3719262535210761 0.037516040892345365
  rotation 0.0002143456675740196 0.00021446890470567024 -0.9999999540295108 1.5702216529193345
  children [
    HingeJoint {
      jointParameters HingeJointParameters {
        position -1.3961226064356577e-08
        axis 0 1 0
        anchor 0 -0.045 -0.0176
      }
      device [
        RotationalMotor {
          name "left wheel motor"
        }
        PositionSensor {
          name "left wheel sensor"
        }
      ]
      endPoint Solid {
        translation 0 -0.045 -0.0176
        rotation -3.094801188683847e-09 -3.0947936224982416e-09 1 1.570799999999999
        children [
          Pose {
            rotation -0.5771969549958951 0.5776567755050862 -0.5771969549958951 2.0939354039397986
            children [
              DEF WHEEL_SHAPE Shape {
                appearance PBRAppearance {
                  roughness 1
                  metalness 0
                }
                geometry Cylinder {
                  height 0.01
                  radius 0.02
                }
              }
            ]
          }
        ]
        name "right wheel"
        boundingObject Pose {
          rotation -0.5771969549958951 0.5776567755050862 -0.5771969549958951 2.0939354039397986
          children [
            USE WHEEL_SHAPE
          ]
        }
        physics DEF WHEEL_PHYSICS Physics {
          density -1
          mass 0.005
        }
        linearVelocity -2.1632974734449407e-16 -9.575470059263222e-17 4.999575431162025e-17
        angularVelocity -2.366028381386523e-15 -1.388325332930936e-14 6.044261649097346e-15
      }
    }
    HingeJoint {
      jointParameters HingeJointParameters {
        position -2.874274945339071e-09
        axis 0 1 0
        anchor 0 0.045 -0.0176
      }
      device [
        RotationalMotor {
          name "right wheel motor"
        }
        PositionSensor {
          name "right wheel sensor"
        }
      ]
      endPoint Solid {
        translation 5.551115123120606e-17 0.044999999999999984 -0.0176
        rotation 2.6058854682608688e-09 2.60587958577423e-09 1 1.5707996938995707
        children [
          Pose {
            rotation -0.5771969549958951 0.5776567755050862 -0.5771969549958951 2.0939354039397986
            children [
              Shape {
                appearance PBRAppearance {
                  roughness 1
                  metalness 0
                }
                geometry Cylinder {
                  height 0.01
                  radius 0.02
                }
              }
            ]
          }
        ]
        name "left wheel"
        boundingObject Pose {
          rotation -0.5771969549958951 0.5776567755050862 -0.5771969549958951 2.0939354039397986
          children [
            Shape {
              appearance PBRAppearance {
                roughness 1
                metalness 0
              }
              geometry Cylinder {
                height 0.01
                radius 0.02
              }
            }
          ]
        }
        physics USE WHEEL_PHYSICS
        linearVelocity -1.8387097499958438e-15 1.5912774773345707e-16 2.0977870770235503e-15
        angularVelocity -4.454631885876124e-15 -3.5917573873419866e-14 6.046670227932467e-15
      }
    }
    DEF BLUE_ROBOT_SHAPE Shape {
      appearance PBRAppearance {
        baseColorMap ImageTexture {
          url [
            "soccer/blue.png"
          ]
        }
        roughness 1
        metalness 0
      }
      geometry Box {
        size 0.075 0.075 0.075
      }
    }
    Solid {
      translation 0 0.0385 0.02
      rotation 0 0 1 1.5707903061004251
      children [
        Shape {
          appearance PBRAppearance {
            baseColor 0 0 1
            roughness 1
            metalness 0
          }
          geometry Box {
            size 0.005 0.005 0.005
          }
        }
        DistanceSensor {
          name "distancesensor left"
          lookupTable [
            0 0 0
            1 1000 0.05
          ]
          type "sonar"
        }
      ]
      name "left sonar"
    }
    Solid {
      translation 0 -0.0385 0.02
      rotation 0 0 1 -1.5707996938995747
      children [
        Shape {
          appearance PBRAppearance {
            baseColor 0 0 1
            roughness 1
            metalness 0
          }
          geometry Box {
            size 0.005 0.005 0.005
          }
        }
        DistanceSensor {
          name "distancesensor right"
          lookupTable [
            0 0 0
            1 1000 0.05
          ]
          type "sonar"
        }
      ]
      name "right sonar"
    }
    Solid {
      translation 0.0385 0 0.02
      children [
        Shape {
          appearance PBRAppearance {
            baseColor 0 0 1
            roughness 1
            metalness 0
          }
          geometry Box {
            size 0.005 0.005 0.005
          }
        }
        DistanceSensor {
          name "distancesensor front"
          lookupTable [
            0 0 0
            1 1000 0.05
          ]
          type "sonar"
        }
      ]
      name "front sonar"
    }
    Solid {
      translation -0.0385 0 0.02
      rotation 0 0 1 3.141592653589793
      children [
        Shape {
          appearance PBRAppearance {
            baseColor 0 0 1
            roughness 1
            metalness 0
          }
          geometry Box {
            size 0.005 0.005 0.005
          }
        }
        DistanceSensor {
          name "distancesensor back"
          lookupTable [
            0 0 0
            1 1000 0.05
          ]
          type "sonar"
        }
      ]
      name "back sonar"
    }
    Receiver {
      name "supervisor receiver"
      channel 1
      allowedChannels [
        1
      ]
    }
    Receiver {
      name "team receiver"
      channel 2
      allowedChannels [
        2
      ]
    }
    Receiver {
      name "ball receiver"
      type "infra-red"
      channel 4
      allowedChannels [
        4
      ]
    }
    Emitter {
      name "team emitter"
      range 10
      channel 2
      baudRate 115200
      allowedChannels [
        2
      ]
    }
    GPS {
    }
    Compass {
    }
  ]
  name "B1"
  boundingObject USE BLUE_ROBOT_SHAPE
  physics DEF ROBOT_PHYSICS Physics {
    density -1
    mass 0.2
  }
  controller "rcj_soccer_team_blue"
  synchronization FALSE
  linearVelocity -5.440582951395796e-16 1.829488015782715e-16 -1.7590246537977234e-16
  angularVelocity -2.9692718316590722e-15 -8.264915095630802e-16 3.748024143342886e-15
}
DEF B2 Robot {
  translation -0.22600444945639184 0.29952893708983774 0.037516017014654277
  rotation 0.003189175070818236 0.003077182500065174 -0.9999901800068984 1.56996989835365
  children [
    HingeJoint {
      jointParameters HingeJointParameters {
        position 1.3478524535099114e-07
        axis 0 1 0
        anchor 0 -0.045 -0.0176
      }
      device [
        RotationalMotor {
          name "left wheel motor"
        }
        PositionSensor {
          name "left wheel sensor"
        }
      ]
      endPoint Solid {
        translation 0 -0.045 -0.0176
        rotation 7.127843433720728e-08 7.127816960027333e-08 0.9999999999999949 1.5708000000000042
        children [
          Pose {
            rotation -0.5771969549958951 0.5776567755050862 -0.5771969549958951 2.0939354039397986
            children [
              DEF WHEEL_SHAPE Shape {
                appearance PBRAppearance {
                  roughness 1
                  metalness 0
                }
                geometry Cylinder {
                  height 0.01
                  radius 0.02
                }
              }
            ]
          }
        ]
        name "right wheel"
        boundingObject Pose {
          rotation -0.5771969549958951 0.5776567755050862 -0.5771969549958951 2.0939354039397986
          children [
            USE WHEEL_SHAPE
          ]
        }
        physics DEF WHEEL_PHYSICS Physics {
          density -1
          mass 0.005
        }
        linearVelocity 3.8893083700516917e-07 0.0008511545410207176 4.454415482875679e-05
        angularVelocity -0.04256508181963936 7.222999618616876e-05 5.8327413229326915e-06
      }
    }
    HingeJoint {
      jointParameters HingeJointParameters {
        position 4.229992744172064e-08
        axis 0 1 0
        anchor 0 0.045 -0.0176
      }
      device [
        RotationalMotor {
          name "right wheel motor"
        }
        PositionSensor {
          name "right wheel sensor"
        }
      ]
      endPoint Solid {
        translation 0 0.044999999999999984 -0.0176
        rotation 2.4601620507586547e-08 2.4601540718999447e-08 0.9999999999999993 1.570799693899572
        children [
          Pose {
            rotation -0.5771969549958951 0.5776567755050862 -0.5771969549958951 2.0939354039397986
            children [
              Shape {
                appearance PBRAppearance {
                  roughness 1
                  metalness 0
                }
                geometry Cylinder {
                  height 0.01
                  radius 0.02
                }
              }
            ]
          }
        ]
        name "left wheel"
        boundingObject Pose {
          rotation -0.5771969549958951 0.5776567755050862 -0.5771969549958951 2.0939354039397986
          children [
            Shape {
              appearance PBRAppearance {
                roughness 1
                metalness 0
              }
              geometry Cylinder {
                height 0.01
                radius 0.02
              }
            }
          ]
        }
        physics USE WHEEL_PHYSICS
        linearVelocity 1.8515952864665841e-06 0.0008513672201855707 3.538805058175205e-05
        angularVelocity -0.04256509032141703 7.228966802804533e-05 5.836351346020233e-06
      }
    }
    DEF BLUE_ROBOT_SHAPE Shape {
      appearance PBRAppearance {
        baseColorMap ImageTexture {
          url [
            "soccer/blue.png"
          ]
        }
        roughness 1
        metalness 0
      }
      geometry Box {
        size 0.075 0.075 0.075
      }
    }
    Solid {
      translation 0 0.0385 0.02
      rotation 0 0 1 1.5707903061004251
      children [
        Shape {
          appearance PBRAppearance {
            baseColor 0 0 1
            roughness 1
            metalness 0
          }
          geometry Box {
            size 0.005 0.005 0.005
          }
        }
        DistanceSensor {
          name "distancesensor left"
          lookupTable [
            0 0 0
            1 1000 0.05
          ]
          type "sonar"
        }
      ]
      name "left sonar"
    }
    Solid {
      translation 0 -0.0385 0.02
      rotation 0 0 1 -1.5707996938995747
      children [
        Shape {
          appearance PBRAppearance {
            baseColor 0 0 1
            roughness 1
            metalness 0
          }
          geometry Box {
            size 0.005 0.005 0.005
          }
        }
        DistanceSensor {
          name "distancesensor right"
          lookupTable [
            0 0 0
            1 1000 0.05
          ]
          type "sonar"
        }
      ]
      name "right sonar"
    }
    Solid {
      translation 0.0385 0 0.02
      children [
        Shape {
          appearance PBRAppearance {
            baseColor 0 0 1
            roughness 1
            metalness 0
          }
          geometry Box {
            size 0.005 0.005 0.005
          }
        }
        DistanceSensor {
          name "distancesensor front"
          lookupTable [
            0 0 0
            1 1000 0.05
          ]
          type "sonar"
        }
      ]
      name "front sonar"
    }
    Solid {
      translation -0.0385 0 0.02
      rotation 0 0 1 3.141592653589793
      children [
        Shape {
          appearance PBRAppearance {
            baseColor 0 0 1
            roughness 1
            metalness 0
          }
          geometry Box {
            size 0.005 0.005 0.005
          }
        }
        DistanceSensor {
          name "distancesensor back"
          lookupTable [
            0 0 0
            1 1000 0.05
          ]
          type "sonar"
        }
      ]
      name "back sonar"
    }
    Receiver {
      name "supervisor receiver"
      channel 1
      allowedChannels [
        1
      ]
    }
    Receiver {
      name "team receiver"
      channel 2
      allowedChannels [
        2
      ]
    }
    Receiver {
      name "ball receiver"
      type "infra-red"
      channel 4
      allowedChannels [
        4
      ]
    }
    Emitter {
      name "team emitter"
      range 10
      channel 2
      baudRate 115200
      allowedChannels [
        2
      ]
    }
    GPS {
    }
    Compass {
    }
  ]
  name "B2"
  boundingObject USE BLUE_ROBOT_SHAPE
  physics USE ROBOT_PHYSICS
  controller "rcj_soccer_team_blue"
  synchronization FALSE
  linearVelocity 1.6090487730859027e-06 0.0016002656820596813 4.270411109832073e-05
  angularVelocity -0.04256508776119755 7.22321326827929e-05 5.83328040202643e-06
}
DEF B3 Robot {
  translation 0.00015530757049982496 0.10859241964532433 0.037516040892345545
  rotation -0.0002143456655970317 -0.00023978663121284452 -0.9999999482791522 1.4588713388045702
  children [
    HingeJoint {
      jointParameters HingeJointParameters {
        position 1.110343236457718e-06
        axis 0 1 0
        anchor 0 -0.045 -0.0176
      }
      device [
        RotationalMotor {
          name "left wheel motor"
        }
        PositionSensor {
          name "left wheel sensor"
        }
      ]
      endPoint Solid {
        translation 0 -0.045 -0.0176
        rotation 5.590574277539733e-07 5.590553749867165e-07 0.9999999999996875 1.5708000000003093
        children [
          Pose {
            rotation -0.5771969549958951 0.5776567755050862 -0.5771969549958951 2.0939354039397986
            children [
              DEF WHEEL_SHAPE Shape {
                appearance PBRAppearance {
                  roughness 1
                  metalness 0
                }
                geometry Cylinder {
                  height 0.01
                  radius 0.02
                }
              }
            ]
          }
        ]
        name "right wheel"
        boundingObject Pose {
          rotation -0.5771969549958951 0.5776567755050862 -0.5771969549958951 2.0939354039397986
          children [
            USE WHEEL_SHAPE
          ]
        }
        physics DEF WHEEL_PHYSICS Physics {
          density -1
          mass 0.005
        }
        linearVelocity 1.2401850453144591e-15 5.477045334573551e-16 2.6144803388285425e-15
        angularVelocity -2.0143297136923395e-14 -4.352787582130008e-15 3.0906436910590854e-16
      }
    }
    HingeJoint {
      jointParameters HingeJointParameters {
        position 1.3446270245625897e-06
        axis 0 1 0
        anchor 0 0.045 -0.0176
      }
      device [
        RotationalMotor {
          name "right wheel motor"
        }
        PositionSensor {
          name "right wheel sensor"
        }
      ]
      endPoint Solid {
        translation 0 0.045 -0.0176
        rotation 6.76186822059271e-07 6.761845488666744e-07 0.9999999999995428 1.570799693900028
        children [
          Pose {
            rotation -0.5771969549958951 0.5776567755050862 -0.5771969549958951 2.0939354039397986
            children [
              Shape {
                appearance PBRAppearance {
                  roughness 1
                  metalness 0
                }
                geometry Cylinder {
                  height 0.01
                  radius 0.02
                }
              }
            ]
          }
        ]
        name "left wheel"
        boundingObject Pose {
          rotation -0.5771969549958951 0.5776567755050862 -0.5771969549958951 2.0939354039397986
          children [
            Shape {
              appearance PBRAppearance {
                roughness 1
                metalness 0
              }
              geometry Cylinder {
                height 0.01
                radius 0.02
              }
            }
          ]
        }
        physics USE WHEEL_PHYSICS
        linearVelocity -5.033106125389036e-16 2.7713806083786037e-16 9.714737655995024e-16
        angularVelocity -4.119560344500817e-15 -4.764693404939901e-14 3.937987618808239e-16
      }
    }
    DEF BLUE_ROBOT_SHAPE Shape {
      appearance PBRAppearance {
        baseColorMap ImageTexture {
          url [
            "soccer/blue.png"
          ]
        }
        roughness 1
        metalness 0
      }
      geometry Box {
        size 0.075 0.075 0.075
      }
    }
    Solid {
      translation 0 0.0385 0.02
      rotation 0 0 1 1.5707903061004251
      children [
        Shape {
          appearance PBRAppearance {
            baseColor 0 0 1
            roughness 1
            metalness 0
          }
          geometry Box {
            size 0.005 0.005 0.005
          }
        }
        DistanceSensor {
          name "distancesensor left"
          lookupTable [
            0 0 0
            1 1000 0.05
          ]
          type "sonar"
        }
      ]
      name "left sonar"
    }
    Solid {
      translation 0 -0.0385 0.02
      rotation 0 0 1 -1.5707996938995747
      children [
        Shape {
          appearance PBRAppearance {
            baseColor 0 0 1
            roughness 1
            metalness 0
          }
          geometry Box {
            size 0.005 0.005 0.005
          }
        }
        DistanceSensor {
          name "distancesensor right"
          lookupTable [
            0 0 0
            1 1000 0.05
          ]
          type "sonar"
        }
      ]
      name "right sonar"
    }
    Solid {
      translation 0.0385 0 0.02
      children [
        Shape {
          appearance PBRAppearance {
            baseColor 0 0 1
            roughness 1
            metalness 0
          }
          geometry Box {
            size 0.005 0.005 0.005
          }
        }
        DistanceSensor {
          name "distancesensor front"
          lookupTable [
            0 0 0
            1 1000 0.05
          ]
          type "sonar"
        }
      ]
      name "front sonar"
    }
    Solid {
      translation -0.0385 0 0.02
      rotation 0 0 1 3.141592653589793
      children [
        Shape {
          appearance PBRAppearance {
            baseColor 0 0 1
            roughness 1
            metalness 0
          }
          geometry Box {
            size 0.005 0.005 0.005
          }
        }
        DistanceSensor {
          name "distancesensor back"
          lookupTable [
            0 0 0
            1 1000 0.05
          ]
          type "sonar"
        }
      ]
      name "back sonar"
    }
    Receiver {
      name "supervisor receiver"
      channel 1
      allowedChannels [
        1
      ]
    }
    Receiver {
      name "team receiver"
      channel 2
      allowedChannels [
        2
      ]
    }
    Receiver {
      name "ball receiver"
      type "infra-red"
      channel 4
      allowedChannels [
        4
      ]
    }
    Emitter {
      name "team emitter"
      range 10
      channel 2
      baudRate 115200
      allowedChannels [
        2
      ]
    }
    GPS {
    }
    Compass {
    }
  ]
  name "B3"
  boundingObject USE BLUE_ROBOT_SHAPE
  physics USE ROBOT_PHYSICS
  controller "rcj_soccer_team_blue"
  synchronization FALSE
  linearVelocity 2.684994472319017e-16 7.996817749201864e-16 8.604374768637667e-16
  angularVelocity -2.3421089213708098e-14 5.829501048987512e-15 3.0469284717860595e-16
}
DEF Y1 Robot {
  translation -0.30606844220128876 -0.3000521012697983 0.037516040892345566
  rotation 0.00021434566725580793 -0.00021494926488205548 0.9999999539263733 1.5679843963218172
  children [
    HingeJoint {
      jointParameters HingeJointParameters {
        position -7.969554919339286e-08
        axis 0 1 0
        anchor 0 -0.045 -0.0176
      }
      device [
        RotationalMotor {
          name "left wheel motor"
        }
        PositionSensor {
          name "left wheel sensor"
        }
      ]
      endPoint Solid {
        translation 1.1102230246250989e-16 -0.04499999999999993 -0.0176
        rotation 3.922540063113147e-08 -3.922526202043656e-08 -0.9999999999999984 1.5708000000000002
        children [
          Pose {
            rotation -0.5771969549958951 0.5776567755050862 -0.5771969549958951 2.0939354039397986
            children [
              DEF WHEEL_SHAPE Shape {
                appearance PBRAppearance {
                  roughness 1
                  metalness 0
                }
                geometry Cylinder {
                  height 0.01
                  radius 0.02
                }
              }
            ]
          }
        ]
        name "right wheel"
        boundingObject Pose {
          rotation -0.5771969549958951 0.5776567755050862 -0.5771969549958951 2.0939354039397986
          children [
            USE WHEEL_SHAPE
          ]
        }
        physics DEF WHEEL_PHYSICS Physics {
          density -1
          mass 0.005
        }
        linearVelocity 4.3300566691810435e-16 -4.109392759768894e-16 4.507162178609629e-16
        angularVelocity 1.7467086411095876e-14 2.2104154290147444e-14 -4.427013373095076e-15
      }
    }
    HingeJoint {
      jointParameters HingeJointParameters {
        position -6.671877657100287e-08
        axis 0 1 0
        anchor 0 0.045 -0.0176
      }
      device [
        RotationalMotor {
          name "right wheel motor"
        }
        PositionSensor {
          name "right wheel sensor"
        }
      ]
      endPoint Solid {
        translation 0 0.04499999999999987 -0.0176
        rotation 3.329047255028182e-08 -3.329035165464108e-08 -0.999999999999999 1.5708000000000002
        children [
          Pose {
            rotation -0.5771969549958951 0.5776567755050862 -0.5771969549958951 2.0939354039397986
            children [
              Shape {
                appearance PBRAppearance {
                  roughness 1
                  metalness 0
                }
                geometry Cylinder {
                  height 0.01
                  radius 0.02
                }
              }
            ]
          }
        ]
        name "left wheel"
        boundingObject Pose {
          rotation -0.5771969549958951 0.5776567755050862 -0.5771969549958951 2.0939354039397986
          children [
            Shape {
              appearance PBRAppearance {
                roughness 1
                metalness 0
              }
              geometry Cylinder {
                height 0.01
                radius 0.02
              }
            }
          ]
        }
        physics USE WHEEL_PHYSICS
        linearVelocity 1.4925467328815933e-15 -2.1136835354262814e-16 1.853573586587526e-15
        angularVelocity 1.7559900561843646e-14 1.6242563759171178e-13 -4.420747117015291e-15
      }
    }
    DEF YELLOW_ROBOT_SHAPE Shape {
      appearance PBRAppearance {
        baseColorMap ImageTexture {
          url [
            "soccer/yellow.png"
          ]
        }
        roughness 1
        metalness 0
      }
      geometry Box {
        size 0.075 0.075 0.075
      }
    }
    Solid {
      translation 0 0.0385 0.02
      rotation 0 0 1 1.5708
      children [
        Shape {
          appearance PBRAppearance {
            baseColor 1 1 0
            roughness 1
            metalness 0
          }
          geometry Box {
            size 0.005 0.005 0.005
          }
        }
        DistanceSensor {
          name "distancesensor left"
          lookupTable [
            0 0 0
            1 1000 0.05
          ]
          type "sonar"
        }
      ]
      name "left sonar"
    }
    Solid {
      translation 0 -0.0385 0.02
      rotation 0 0 1 -1.5707996938995747
      children [
        Shape {
          appearance PBRAppearance {
            baseColor 1 1 0
            roughness 1
            metalness 0
          }
          geometry Box {
            size 0.005 0.005 0.005
          }
        }
        DistanceSensor {
          name "distancesensor right"
          lookupTable [
            0 0 0
            1 1000 0.05
          ]
          type "sonar"
        }
      ]
      name "right sonar"
    }
    Solid {
      translation 0.0385 0 0.02
      children [
        Shape {
          appearance PBRAppearance {
            baseColor 1 1 0
            roughness 1
            metalness 0
          }
          geometry Box {
            size 0.005 0.005 0.005
          }
        }
        DistanceSensor {
          name "distancesensor front"
          lookupTable [
            0 0 0
            1 1000 0.05
          ]
          type "sonar"
        }
      ]
      name "front sonar"
    }
    Solid {
      translation -0.0385 0 0.02
      rotation 0 0 1 3.141592653589793
      children [
        Shape {
          appearance PBRAppearance {
            baseColor 1 1 0
            roughness 1
            metalness 0
          }
          geometry Box {
            size 0.005 0.005 0.005
          }
        }
        DistanceSensor {
          name "distancesensor back"
          lookupTable [
            0 0 0
            1 1000 0.05
          ]
          type "sonar"
        }
      ]
      name "back sonar"
    }
    Receiver {
      name "supervisor receiver"
      channel 1
      allowedChannels [
        1
      ]
    }
    Receiver {
      name "team receiver"
      channel 3
      allowedChannels [
        3
      ]
    }
    Receiver {
      name "ball receiver"
      type "infra-red"
      channel 4
      allowedChannels [
        4
      ]
    }
    Emitter {
      name "team emitter"
      range 10
      channel 3
      baudRate 115200
      allowedChannels [
        3
      ]
    }
    GPS {
    }
    Compass {
    }
  ]
  name "Y1"
  boundingObject USE YELLOW_ROBOT_SHAPE
  physics USE ROBOT_PHYSICS
  controller "rcj_soccer_team_yellow"
  synchronization FALSE
  linearVelocity 4.2121938321792104e-16 -7.130271074569237e-16 6.765814568137062e-16
  angularVelocity 1.6970229546227863e-14 1.2173713166808465e-15 -2.871272196662224e-15
}
DEF Y2 Robot {
  translation 0.5136429581408628 0.037911104491116 0.03815458189599253
  rotation 0.010568821542066604 0.06743922778427144 -0.9976674047833142 0.5055813640066259
  children [
    HingeJoint {
      jointParameters HingeJointParameters {
        position 791.1801698982674
        axis 0 1 0
        anchor 0 -0.045 -0.0176
      }
      device [
        RotationalMotor {
          name "left wheel motor"
        }
        PositionSensor {
          name "left wheel sensor"
        }
      ]
      endPoint Solid {
        translation 0 -0.044999999999999984 -0.0176
        rotation 0.2406853764019079 -0.2406844923167794 -0.9402880009574119 1.6323301976957798
        children [
          Pose {
            rotation -0.5771969549958951 0.5776567755050862 -0.5771969549958951 2.0939354039397986
            children [
              DEF WHEEL_SHAPE Shape {
                appearance PBRAppearance {
                  roughness 1
                  metalness 0
                }
                geometry Cylinder {
                  height 0.01
                  radius 0.02
                }
              }
            ]
          }
        ]
        name "right wheel"
        boundingObject Pose {
          rotation -0.5771969549958951 0.5776567755050862 -0.5771969549958951 2.0939354039397986
          children [
            USE WHEEL_SHAPE
          ]
        }
        physics DEF WHEEL_PHYSICS Physics {
          density -1
          mass 0.005
        }
        linearVelocity 0.07145471920918364 -0.08130708492764127 0.023492098162592356
        angularVelocity 4.495432077973703 7.439626859833685 3.336117576248146
      }
    }
    HingeJoint {
      jointParameters HingeJointParameters {
        position 822.8468280780445
        axis 0 1 0
        anchor 0 0.045 -0.0176
      }
      device [
        RotationalMotor {
          name "right wheel motor"
        }
        PositionSensor {
          name "right wheel sensor"
        }
      ]
      endPoint Solid {
        translation -1.071979428242285e-16 0.044999999999999984 -0.01760000000000003
        rotation -0.12393368435564493 0.12393322912264007 0.9845206938410541 4.696785578889806
        children [
          Pose {
            rotation -0.5771969549958951 0.5776567755050862 -0.5771969549958951 2.0939354039397986
            children [
              Shape {
                appearance PBRAppearance {
                  roughness 1
                  metalness 0
                }
                geometry Cylinder {
                  height 0.01
                  radius 0.02
                }
              }
            ]
          }
        ]
        name "left wheel"
        boundingObject Pose {
          rotation -0.5771969549958951 0.5776567755050862 -0.5771969549958951 2.0939354039397986
          children [
            Shape {
              appearance PBRAppearance {
                roughness 1
                metalness 0
              }
              geometry Cylinder {
                height 0.01
                radius 0.02
              }
            }
          ]
        }
        physics USE WHEEL_PHYSICS
        linearVelocity -0.17359630065255277 0.07162462804692182 0.005242593153734818
        angularVelocity -6.555871950674806 -9.233841086413703 3.0165667788444805
      }
    }
    DEF YELLOW_ROBOT_SHAPE Shape {
      appearance PBRAppearance {
        baseColorMap ImageTexture {
          url [
            "soccer/yellow.png"
          ]
        }
        roughness 1
        metalness 0
      }
      geometry Box {
        size 0.075 0.075 0.075
      }
    }
    Solid {
      translation 0 0.0385 0.02
      rotation 0 0 1 1.5708
      children [
        Shape {
          appearance PBRAppearance {
            baseColor 1 1 0
            roughness 1
            metalness 0
          }
          geometry Box {
            size 0.005 0.005 0.005
          }
        }
        DistanceSensor {
          name "distancesensor left"
          lookupTable [
            0 0 0
            1 1000 0.05
          ]
          type "sonar"
        }
      ]
      name "left sonar"
    }
    Solid {
      translation 0 -0.0385 0.02
      rotation 0 0 1 -1.5707996938995747
      children [
        Shape {
          appearance PBRAppearance {
            baseColor 1 1 0
            roughness 1
            metalness 0
          }
          geometry Box {
            size 0.005 0.005 0.005
          }
        }
        DistanceSensor {
          name "distancesensor right"
          lookupTable [
            0 0 0
            1 1000 0.05
          ]
          type "sonar"
        }
      ]
      name "right sonar"
    }
    Solid {
      translation 0.0385 0 0.02
      children [
        Shape {
          appearance PBRAppearance {
            baseColor 1 1 0
            roughness 1
            metalness 0
          }
          geometry Box {
            size 0.005 0.005 0.005
          }
        }
        DistanceSensor {
          name "distancesensor front"
          lookupTable [
            0 0 0
            1 1000 0.05
          ]
          type "sonar"
        }
      ]
      name "front sonar"
    }
    Solid {
      translation -0.0385 0 0.02
      rotation 0 0 1 3.141592653589793
      children [
        Shape {
          appearance PBRAppearance {
            baseColor 1 1 0
            roughness 1
            metalness 0
          }
          geometry Box {
            size 0.005 0.005 0.005
          }
        }
        DistanceSensor {
          name "distancesensor back"
          lookupTable [
            0 0 0
            1 1000 0.05
          ]
          type "sonar"
        }
      ]
      name "back sonar"
    }
    Receiver {
      name "supervisor receiver"
      channel 1
      allowedChannels [
        1
      ]
    }
    Receiver {
      name "team receiver"
      channel 3
      allowedChannels [
        3
      ]
    }
    Receiver {
      name "ball receiver"
      type "infra-red"
      channel 4
      allowedChannels [
        4
      ]
    }
    Emitter {
      name "team emitter"
      range 10
      channel 3
      baudRate 115200
      allowedChannels [
        3
      ]
    }
    GPS {
    }
    Compass {
    }
  ]
  name "Y2"
  boundingObject USE YELLOW_ROBOT_SHAPE
  physics USE ROBOT_PHYSICS
  controller "rcj_soccer_team_yellow"
  synchronization FALSE
  linearVelocity -0.06433883227028166 0.01594387281181596 0.015011810184879971
  angularVelocity -0.9610975021736166 -0.9457042326271363 3.236207085725308
}
DEF Y3 Robot {
  translation -0.12396233082364332 0.2961220081431727 0.03752881576188086
  rotation 0.0019789830047740173 0.0014586123815772299 0.9999969780335275 -1.7707189108298858
  children [
    HingeJoint {
      jointParameters HingeJointParameters {
        position 652.118568884863
        axis 0 1 0
        anchor 0 -0.045 -0.0176
      }
      device [
        RotationalMotor {
          name "left wheel motor"
        }
        PositionSensor {
          name "left wheel sensor"
        }
      ]
      endPoint Solid {
        translation 0 -0.04499999999999999 -0.0176
        rotation 0.5257858854431606 -0.5257839541273106 -0.6686556933512207 1.9628393317266495
        children [
          Pose {
            rotation -0.5771969549958951 0.5776567755050862 -0.5771969549958951 2.0939354039397986
            children [
              DEF WHEEL_SHAPE Shape {
                appearance PBRAppearance {
                  roughness 1
                  metalness 0
                }
                geometry Cylinder {
                  height 0.01
                  radius 0.02
                }
              }
            ]
          }
        ]
        name "right wheel"
        boundingObject Pose {
          rotation -0.5771969549958951 0.5776567755050862 -0.5771969549958951 2.0939354039397986
          children [
            USE WHEEL_SHAPE
          ]
        }
        physics DEF WHEEL_PHYSICS Physics {
          density -1
          mass 0.005
        }
        linearVelocity -0.038450153156439355 -0.19679886806416172 -5.061933681883233e-05
        angularVelocity 9.829704202673708 -1.9710521461778516 -0.011572427350599135
      }
    }
    HingeJoint {
      jointParameters HingeJointParameters {
        position 678.7576037794154
        axis 0 1 0
        anchor 0 0.045 -0.0176
      }
      device [
        RotationalMotor {
          name "right wheel motor"
        }
        PositionSensor {
          name "right wheel sensor"
        }
      ]
      endPoint Solid {
        translation 0 0.04499999999999999 -0.0176
        rotation -0.0863624884702208 0.08636217124367093 -0.992513524322621 1.5783145691642828
        children [
          Pose {
            rotation -0.5771969549958951 0.5776567755050862 -0.5771969549958951 2.0939354039397986
            children [
              Shape {
                appearance PBRAppearance {
                  roughness 1
                  metalness 0
                }
                geometry Cylinder {
                  height 0.01
                  radius 0.02
                }
              }
            ]
          }
        ]
        name "left wheel"
        boundingObject Pose {
          rotation -0.5771969549958951 0.5776567755050862 -0.5771969549958951 2.0939354039397986
          children [
            Shape {
              appearance PBRAppearance {
                roughness 1
                metalness 0
              }
              geometry Cylinder {
                height 0.01
                radius 0.02
              }
            }
          ]
        }
        physics USE WHEEL_PHYSICS
        linearVelocity -0.0394357752047564 -0.19645488390600083 -5.905113354683237e-06
        angularVelocity 9.829875051657057 -1.9702242765757418 0.002922739405683712
      }
    }
    DEF YELLOW_ROBOT_SHAPE Shape {
      appearance PBRAppearance {
        baseColorMap ImageTexture {
          url [
            "soccer/yellow.png"
          ]
        }
        roughness 1
        metalness 0
      }
      geometry Box {
        size 0.075 0.075 0.075
      }
    }
    Solid {
      translation 0 0.0385 0.02
      rotation 0 0 1 1.5708
      children [
        Shape {
          appearance PBRAppearance {
            baseColor 1 1 0
            roughness 1
            metalness 0
          }
          geometry Box {
            size 0.005 0.005 0.005
          }
        }
        DistanceSensor {
          name "distancesensor left"
          lookupTable [
            0 0 0
            1 1000 0.05
          ]
          type "sonar"
        }
      ]
      name "left sonar"
    }
    Solid {
      translation 0 -0.0385 0.02
      rotation 0 0 1 -1.5707996938995747
      children [
        Shape {
          appearance PBRAppearance {
            baseColor 1 1 0
            roughness 1
            metalness 0
          }
          geometry Box {
            size 0.005 0.005 0.005
          }
        }
        DistanceSensor {
          name "distancesensor right"
          lookupTable [
            0 0 0
            1 1000 0.05
          ]
          type "sonar"
        }
      ]
      name "right sonar"
    }
    Solid {
      translation 0.0385 0 0.02
      children [
        Shape {
          appearance PBRAppearance {
            baseColor 1 1 0
            roughness 1
            metalness 0
          }
          geometry Box {
            size 0.005 0.005 0.005
          }
        }
        DistanceSensor {
          name "distancesensor front"
          lookupTable [
            0 0 0
            1 1000 0.05
          ]
          type "sonar"
        }
      ]
      name "front sonar"
    }
    Solid {
      translation -0.0385 0 0.02
      rotation 0 0 1 3.141592653589793
      children [
        Shape {
          appearance PBRAppearance {
            baseColor 1 1 0
            roughness 1
            metalness 0
          }
          geometry Box {
            size 0.005 0.005 0.005
          }
        }
        DistanceSensor {
          name "distancesensor back"
          lookupTable [
            0 0 0
            1 1000 0.05
          ]
          type "sonar"
        }
      ]
      name "back sonar"
    }
    Receiver {
      name "supervisor receiver"
      channel 1
      allowedChannels [
        1
      ]
    }
    Receiver {
      name "team receiver"
      channel 3
      allowedChannels [
        3
      ]
    }
    Receiver {
      name "ball receiver"
      type "infra-red"
      channel 4
      allowedChannels [
        4
      ]
    }
    Emitter {
      name "team emitter"
      range 10
      channel 3
      baudRate 115200
      allowedChannels [
        3
      ]
    }
    GPS {
    }
    Compass {
    }
  ]
  name "Y3"
  boundingObject USE YELLOW_ROBOT_SHAPE
  physics USE ROBOT_PHYSICS
  controller "rcj_soccer_team_yellow"
  synchronization FALSE
  linearVelocity -0.039047680181185304 -0.197064612001285 -8.411586569832268e-05
  angularVelocity 0.024710176038509144 -0.005733611644290794 -0.0013126709344549003
}
Robot {
  children [
    Emitter {
      range 10
      channel 1
      baudRate 115200
      allowedChannels [
        1
      ]
    }
  ]
  controller "rcj_soccer_referee_supervisor"
  supervisor TRUE
}
